Workbook

Sheet Dashboard
A1: UPPER BODY PROGRAM - DASHBOARD
A4: 📅 CONSISTENCY TRACKER
A5: Week | B5: Push Date | C5: Push Done? | D5: Pull Date | E5: Pull Done? | F5: Week Complete?
A6: Week 1 | B6: 45994 | C6: YES | D6: 45997 | E6: YES | F6: =IF(AND(UPPER(C6)="YES",UPPER(E6)="YES"),"✓ COMPLETE","incomplete") -> ✓ COMPLETE
A7: Week 2 | B7: 46002 | C7: Yes | F7: =IF(AND(UPPER(C7)="YES",UPPER(E7)="YES"),"✓ COMPLETE","incomplete") -> incomplete
A8: Week 3 | F8: =IF(AND(UPPER(C8)="YES",UPPER(E8)="YES"),"✓ COMPLETE","incomplete") -> incomplete
A9: Week 4 | F9: =IF(AND(UPPER(C9)="YES",UPPER(E9)="YES"),"✓ COMPLETE","incomplete") -> incomplete
A10: Week 5 | F10: =IF(AND(UPPER(C10)="YES",UPPER(E10)="YES"),"✓ COMPLETE","incomplete") -> incomplete
A11: Week 6 | F11: =IF(AND(UPPER(C11)="YES",UPPER(E11)="YES"),"✓ COMPLETE","incomplete") -> incomplete
A12: Week 7 | F12: =IF(AND(UPPER(C12)="YES",UPPER(E12)="YES"),"✓ COMPLETE","incomplete") -> incomplete
A13: Week 8 | F13: =IF(AND(UPPER(C13)="YES",UPPER(E13)="YES"),"✓ COMPLETE","incomplete") -> incomplete
A14: TOTALS: | C14: =COUNTIF(C6:C13,"YES") -> 2 | E14: =COUNTIF(E6:E13,"YES") -> 1 | F14: =COUNTIF(F6:F13,"✓ COMPLETE") -> 1
A15: Current Streak: | B15: =COUNTIF(F6:F13,"✓ COMPLETE")&" weeks" -> 1 weeks | D15: Completion Rate: | E15: =IF(COUNTA(C6:C13)>0,(C14+E14)/(COUNTA(C6:C13)+COUNTA(E6:E13)),0) -> 1
A18: 📊 SESSION VOLUME OVERVIEW
A19: Week | B19: Session A | C19: Session B | D19: Total Volume | E19: Progress %
A20: Week 1 | B20: =SUMIF('Session A'!J:J,1,'Session A'!G:G) -> 2564 | C20: =SUMIF('Session B'!J:J,1,'Session B'!G:G) -> 2952.5 | D20: =B20+C20 -> 5516.5 | E20: -
A21: Week 2 | B21: =SUMIF('Session A'!J:J,2,'Session A'!G:G) -> 3105 | C21: =SUMIF('Session B'!J:J,2,'Session B'!G:G) -> 0 | D21: =B21+C21 -> 3105 | E21: =IF(D20>0,(D21-D20)/D20,0) -> -0.43714312
A22: Week 3 | B22: =SUMIF('Session A'!J:J,3,'Session A'!G:G) -> 0 | C22: =SUMIF('Session B'!J:J,3,'Session B'!G:G) -> 0 | D22: =B22+C22 -> 0 | E22: =IF(D21>0,(D22-D21)/D21,0) -> -1
A23: Week 4 | B23: =SUMIF('Session A'!J:J,4,'Session A'!G:G) -> 0 | C23: =SUMIF('Session B'!J:J,4,'Session B'!G:G) -> 0 | D23: =B23+C23 -> 0 | E23: =IF(D22>0,(D23-D22)/D22,0) -> 0
A26: 🎯 WEEKLY SETS PER MUSCLE (vs Recommended 10-20 sets/week)
A27: Muscle | B27: Week 1 | C27: Week 2 | D27: Week 3 | E27: Week 4 | F27: Average | G27: Status
A28: Chest | B28: =SUMIFS('Session A'!L:L,'Session A'!J:J,1,'Session A'!K:K,"Chest")+SUMIFS('Session B'!L:L,'Session B'!J:J,1,'Session B'!K:K,"Chest") -> 8 | C28: =SUMIFS('Session A'!L:L,'Session A'!J:J,2,'Session A'!K:K,"Chest")+SUMIFS('Session B'!L:L,'Session B'!J:J,2,'Session B'!K:K,"Chest") -> 6 | D28: =SUMIFS('Session A'!L:L,'Session A'!J:J,3,'Session A'!K:K,"Chest")+SUMIFS('Session B'!L:L,'Session B'!J:J,3,'Session B'!K:K,"Chest") -> 7 | E28: =SUMIFS('Session A'!L:L,'Session A'!J:J,2,'Session A'!K:K,"Chest")+SUMIFS('Session B'!L:L,'Session B'!J:J,2,'Session B'!K:K,"Chest") -> 6 | F28: =ROUND(AVERAGE(B28:E28),1) -> 6.8 | G28: =IF(F28<6,"⚠️ Low",IF(F28>12,"⚠️ High","✓ Good")) -> ✓ Good
A29: Shoulders | B29: =SUMIFS('Session A'!L:L,'Session A'!J:J,1,'Session A'!K:K,"Shoulders")+SUMIFS('Session B'!L:L,'Session B'!J:J,1,'Session B'!K:K,"Shoulders") -> 4 | C29: =SUMIFS('Session A'!L:L,'Session A'!J:J,2,'Session A'!K:K,"Shoulders")+SUMIFS('Session B'!L:L,'Session B'!J:J,2,'Session B'!K:K,"Shoulders") -> 4 | D29: =SUMIFS('Session A'!L:L,'Session A'!J:J,3,'Session A'!K:K,"Shoulders")+SUMIFS('Session B'!L:L,'Session B'!J:J,3,'Session B'!K:K,"Shoulders") -> 2 | E29: =SUMIFS('Session A'!L:L,'Session A'!J:J,2,'Session A'!K:K,"Shoulders")+SUMIFS('Session B'!L:L,'Session B'!J:J,2,'Session B'!K:K,"Shoulders") -> 4 | F29: =ROUND(AVERAGE(B29:E29),1) -> 3.5 | G29: =IF(F29<6,"⚠️ Low",IF(F29>12,"⚠️ High","✓ Good")) -> ⚠️ Low
A30: Triceps | B30: =SUMIFS('Session A'!L:L,'Session A'!J:J,1,'Session A'!K:K,"Triceps")+SUMIFS('Session B'!L:L,'Session B'!J:J,1,'Session B'!K:K,"Chest") -> 4 | C30: =SUMIFS('Session A'!L:L,'Session A'!J:J,2,'Session A'!K:K,"Triceps")+SUMIFS('Session B'!L:L,'Session B'!J:J,2,'Session B'!K:K,"Triceps") -> 4 | D30: =SUMIFS('Session A'!L:L,'Session A'!J:J,3,'Session A'!K:K,"Triceps")+SUMIFS('Session B'!L:L,'Session B'!J:J,3,'Session B'!K:K,"Triceps") -> 2 | E30: =SUMIFS('Session A'!L:L,'Session A'!J:J,2,'Session A'!K:K,"Triceps")+SUMIFS('Session B'!L:L,'Session B'!J:J,2,'Session B'!K:K,"Triceps") -> 4 | F30: =ROUND(AVERAGE(B30:E30),1) -> 3.5 | G30: =IF(F30<6,"⚠️ Low",IF(F30>12,"⚠️ High","✓ Good")) -> ⚠️ Low
A31: Back | B31: =SUMIFS('Session A'!L:L,'Session A'!J:J,1,'Session A'!K:K,"Back")+SUMIFS('Session B'!L:L,'Session B'!J:J,1,'Session B'!K:K,"Back") -> 6 | C31: =SUMIFS('Session A'!L:L,'Session A'!J:J,2,'Session A'!K:K,"Back")+SUMIFS('Session B'!L:L,'Session B'!J:J,2,'Session B'!K:K,"Back") -> 6 | D31: =SUMIFS('Session A'!L:L,'Session A'!J:J,2,'Session A'!K:K,"Back")+SUMIFS('Session B'!L:L,'Session B'!J:J,2,'Session B'!K:K,"Back") -> 6 | E31: =SUMIFS('Session A'!L:L,'Session A'!J:J,2,'Session A'!K:K,"Back")+SUMIFS('Session B'!L:L,'Session B'!J:J,2,'Session B'!K:K,"Back") -> 6 | F31: =ROUND(AVERAGE(B31:E31),1) -> 6 | G31: =IF(F31<6,"⚠️ Low",IF(F31>12,"⚠️ High","✓ Good")) -> ✓ Good
A32: Rear Delts | B32: =SUMIFS('Session A'!L:L,'Session A'!J:J,1,'Session A'!K:K,"Rear Delts")+SUMIFS('Session B'!L:L,'Session B'!J:J,1,'Session B'!K:K,"Rear Delts") -> 2 | C32: =SUMIFS('Session A'!L:L,'Session A'!J:J,2,'Session A'!K:K,"Rear Delts")+SUMIFS('Session B'!L:L,'Session B'!J:J,2,'Session B'!K:K,"Rear Delts") -> 2 | D32: =SUMIFS('Session A'!L:L,'Session A'!J:J,2,'Session A'!K:K,"Rear Delts")+SUMIFS('Session B'!L:L,'Session B'!J:J,2,'Session B'!K:K,"Rear Delts") -> 2 | E32: =SUMIFS('Session A'!L:L,'Session A'!J:J,2,'Session A'!K:K,"Rear Delts")+SUMIFS('Session B'!L:L,'Session B'!J:J,2,'Session B'!K:K,"Rear Delts") -> 2 | F32: =ROUND(AVERAGE(B32:E32),1) -> 2 | G32: =IF(F32<6,"⚠️ Low",IF(F32>12,"⚠️ High","✓ Good")) -> ⚠️ Low
A33: Biceps | B33: =SUMIFS('Session A'!L:L,'Session A'!J:J,1,'Session A'!K:K,"Biceps")+SUMIFS('Session B'!L:L,'Session B'!J:J,1,'Session B'!K:K,"Biceps") -> 4 | C33: =SUMIFS('Session A'!L:L,'Session A'!J:J,2,'Session A'!K:K,"Biceps")+SUMIFS('Session B'!L:L,'Session B'!J:J,2,'Session B'!K:K,"Biceps") -> 4 | D33: =SUMIFS('Session A'!L:L,'Session A'!J:J,2,'Session A'!K:K,"Biceps")+SUMIFS('Session B'!L:L,'Session B'!J:J,2,'Session B'!K:K,"Biceps") -> 4 | E33: =SUMIFS('Session A'!L:L,'Session A'!J:J,2,'Session A'!K:K,"Biceps")+SUMIFS('Session B'!L:L,'Session B'!J:J,2,'Session B'!K:K,"Biceps") -> 4 | F33: =ROUND(AVERAGE(B33:E33),1) -> 4 | G33: =IF(F33<6,"⚠️ Low",IF(F33>12,"⚠️ High","✓ Good")) -> ⚠️ Low
A34: Core | B34: =SUMIFS('Session A'!L:L,'Session A'!J:J,1,'Session A'!K:K,"Core")+SUMIFS('Session B'!L:L,'Session B'!J:J,1,'Session B'!K:K,"Core") -> 4 | C34: =SUMIFS('Session A'!L:L,'Session A'!J:J,2,'Session A'!K:K,"Core")+SUMIFS('Session B'!L:L,'Session B'!J:J,2,'Session B'!K:K,"Core") -> 2 | D34: =SUMIFS('Session A'!L:L,'Session A'!J:J,2,'Session A'!K:K,"Core")+SUMIFS('Session B'!L:L,'Session B'!J:J,2,'Session B'!K:K,"Core") -> 2 | E34: =SUMIFS('Session A'!L:L,'Session A'!J:J,2,'Session A'!K:K,"Core")+SUMIFS('Session B'!L:L,'Session B'!J:J,2,'Session B'!K:K,"Core") -> 2 | F34: =ROUND(AVERAGE(B34:E34),1) -> 2.5 | G34: =IF(F34<6,"⚠️ Low",IF(F34>12,"⚠️ High","✓ Good")) -> ⚠️ Low
A37: 📈 VOLUME BY MUSCLE GROUP
A38: Muscle | B38: Week 1 | C38: Week 2 | D38: Week 3 | E38: Week 4 | F38: Progress %
A39: Chest | B39: =SUMIFS('Upper A - Push'!G:G,'Upper A - Push'!J:J,1,'Upper A - Push'!K:K,"Chest")+SUMIFS('Upper B - Pull'!G:G,'Upper B - Pull'!J:J,1,'Upper B - Pull'!K:K,"Chest") -> #N/A | C39: =SUMIFS('Upper A - Push'!G:G,'Upper A - Push'!J:J,2,'Upper A - Push'!K:K,"Chest")+SUMIFS('Upper B - Pull'!G:G,'Upper B - Pull'!J:J,2,'Upper B - Pull'!K:K,"Chest") -> #N/A | D39: =SUMIFS('Upper A - Push'!G:G,'Upper A - Push'!J:J,3,'Upper A - Push'!K:K,"Chest")+SUMIFS('Upper B - Pull'!G:G,'Upper B - Pull'!J:J,3,'Upper B - Pull'!K:K,"Chest") -> #N/A | E39: =SUMIFS('Upper A - Push'!G:G,'Upper A - Push'!J:J,4,'Upper A - Push'!K:K,"Chest")+SUMIFS('Upper B - Pull'!G:G,'Upper B - Pull'!J:J,4,'Upper B - Pull'!K:K,"Chest") -> #N/A | F39: =IF(B39>0,(E39-B39)/B39,0) -> #N/A
A40: Shoulders | B40: =SUMIFS('Upper A - Push'!G:G,'Upper A - Push'!J:J,1,'Upper A - Push'!K:K,"Shoulders")+SUMIFS('Upper B - Pull'!G:G,'Upper B - Pull'!J:J,1,'Upper B - Pull'!K:K,"Shoulders") -> #N/A | C40: =SUMIFS('Upper A - Push'!G:G,'Upper A - Push'!J:J,2,'Upper A - Push'!K:K,"Shoulders")+SUMIFS('Upper B - Pull'!G:G,'Upper B - Pull'!J:J,2,'Upper B - Pull'!K:K,"Shoulders") -> #N/A | D40: =SUMIFS('Upper A - Push'!G:G,'Upper A - Push'!J:J,3,'Upper A - Push'!K:K,"Shoulders")+SUMIFS('Upper B - Pull'!G:G,'Upper B - Pull'!J:J,3,'Upper B - Pull'!K:K,"Shoulders") -> #N/A | E40: =SUMIFS('Upper A - Push'!G:G,'Upper A - Push'!J:J,4,'Upper A - Push'!K:K,"Shoulders")+SUMIFS('Upper B - Pull'!G:G,'Upper B - Pull'!J:J,4,'Upper B - Pull'!K:K,"Shoulders") -> #N/A | F40: =IF(B40>0,(E40-B40)/B40,0) -> #N/A
A41: Triceps | B41: =SUMIFS('Upper A - Push'!G:G,'Upper A - Push'!J:J,1,'Upper A - Push'!K:K,"Triceps")+SUMIFS('Upper B - Pull'!G:G,'Upper B - Pull'!J:J,1,'Upper B - Pull'!K:K,"Triceps") -> #N/A | C41: =SUMIFS('Upper A - Push'!G:G,'Upper A - Push'!J:J,2,'Upper A - Push'!K:K,"Triceps")+SUMIFS('Upper B - Pull'!G:G,'Upper B - Pull'!J:J,2,'Upper B - Pull'!K:K,"Triceps") -> #N/A | D41: =SUMIFS('Upper A - Push'!G:G,'Upper A - Push'!J:J,3,'Upper A - Push'!K:K,"Triceps")+SUMIFS('Upper B - Pull'!G:G,'Upper B - Pull'!J:J,3,'Upper B - Pull'!K:K,"Triceps") -> #N/A | E41: =SUMIFS('Upper A - Push'!G:G,'Upper A - Push'!J:J,4,'Upper A - Push'!K:K,"Triceps")+SUMIFS('Upper B - Pull'!G:G,'Upper B - Pull'!J:J,4,'Upper B - Pull'!K:K,"Triceps") -> #N/A | F41: =IF(B41>0,(E41-B41)/B41,0) -> #N/A
A42: Back | B42: =SUMIFS('Upper A - Push'!G:G,'Upper A - Push'!J:J,1,'Upper A - Push'!K:K,"Back")+SUMIFS('Upper B - Pull'!G:G,'Upper B - Pull'!J:J,1,'Upper B - Pull'!K:K,"Back") -> #N/A | C42: =SUMIFS('Upper A - Push'!G:G,'Upper A - Push'!J:J,2,'Upper A - Push'!K:K,"Back")+SUMIFS('Upper B - Pull'!G:G,'Upper B - Pull'!J:J,2,'Upper B - Pull'!K:K,"Back") -> #N/A | D42: =SUMIFS('Upper A - Push'!G:G,'Upper A - Push'!J:J,3,'Upper A - Push'!K:K,"Back")+SUMIFS('Upper B - Pull'!G:G,'Upper B - Pull'!J:J,3,'Upper B - Pull'!K:K,"Back") -> #N/A | E42: =SUMIFS('Upper A - Push'!G:G,'Upper A - Push'!J:J,4,'Upper A - Push'!K:K,"Back")+SUMIFS('Upper B - Pull'!G:G,'Upper B - Pull'!J:J,4,'Upper B - Pull'!K:K,"Back") -> #N/A | F42: =IF(B42>0,(E42-B42)/B42,0) -> #N/A
A43: Rear Delts | B43: =SUMIFS('Upper A - Push'!G:G,'Upper A - Push'!J:J,1,'Upper A - Push'!K:K,"Rear Delts")+SUMIFS('Upper B - Pull'!G:G,'Upper B - Pull'!J:J,1,'Upper B - Pull'!K:K,"Rear Delts") -> #N/A | C43: =SUMIFS('Upper A - Push'!G:G,'Upper A - Push'!J:J,2,'Upper A - Push'!K:K,"Rear Delts")+SUMIFS('Upper B - Pull'!G:G,'Upper B - Pull'!J:J,2,'Upper B - Pull'!K:K,"Rear Delts") -> #N/A | D43: =SUMIFS('Upper A - Push'!G:G,'Upper A - Push'!J:J,3,'Upper A - Push'!K:K,"Rear Delts")+SUMIFS('Upper B - Pull'!G:G,'Upper B - Pull'!J:J,3,'Upper B - Pull'!K:K,"Rear Delts") -> #N/A | E43: =SUMIFS('Upper A - Push'!G:G,'Upper A - Push'!J:J,4,'Upper A - Push'!K:K,"Rear Delts")+SUMIFS('Upper B - Pull'!G:G,'Upper B - Pull'!J:J,4,'Upper B - Pull'!K:K,"Rear Delts") -> #N/A | F43: =IF(B43>0,(E43-B43)/B43,0) -> #N/A
A44: Biceps | B44: =SUMIFS('Upper A - Push'!G:G,'Upper A - Push'!J:J,1,'Upper A - Push'!K:K,"Biceps")+SUMIFS('Upper B - Pull'!G:G,'Upper B - Pull'!J:J,1,'Upper B - Pull'!K:K,"Biceps") -> #N/A | C44: =SUMIFS('Upper A - Push'!G:G,'Upper A - Push'!J:J,2,'Upper A - Push'!K:K,"Biceps")+SUMIFS('Upper B - Pull'!G:G,'Upper B - Pull'!J:J,2,'Upper B - Pull'!K:K,"Biceps") -> #N/A | D44: =SUMIFS('Upper A - Push'!G:G,'Upper A - Push'!J:J,3,'Upper A - Push'!K:K,"Biceps")+SUMIFS('Upper B - Pull'!G:G,'Upper B - Pull'!J:J,3,'Upper B - Pull'!K:K,"Biceps") -> #N/A | E44: =SUMIFS('Upper A - Push'!G:G,'Upper A - Push'!J:J,4,'Upper A - Push'!K:K,"Biceps")+SUMIFS('Upper B - Pull'!G:G,'Upper B - Pull'!J:J,4,'Upper B - Pull'!K:K,"Biceps") -> #N/A | F44: =IF(B44>0,(E44-B44)/B44,0) -> #N/A
A45: Core | B45: =SUMIFS('Upper A - Push'!G:G,'Upper A - Push'!J:J,1,'Upper A - Push'!K:K,"Core")+SUMIFS('Upper B - Pull'!G:G,'Upper B - Pull'!J:J,1,'Upper B - Pull'!K:K,"Core") -> #N/A | C45: =SUMIFS('Upper A - Push'!G:G,'Upper A - Push'!J:J,2,'Upper A - Push'!K:K,"Core")+SUMIFS('Upper B - Pull'!G:G,'Upper B - Pull'!J:J,2,'Upper B - Pull'!K:K,"Core") -> #N/A | D45: =SUMIFS('Upper A - Push'!G:G,'Upper A - Push'!J:J,3,'Upper A - Push'!K:K,"Core")+SUMIFS('Upper B - Pull'!G:G,'Upper B - Pull'!J:J,3,'Upper B - Pull'!K:K,"Core") -> #N/A | E45: =SUMIFS('Upper A - Push'!G:G,'Upper A - Push'!J:J,4,'Upper A - Push'!K:K,"Core")+SUMIFS('Upper B - Pull'!G:G,'Upper B - Pull'!J:J,4,'Upper B - Pull'!K:K,"Core") -> #N/A | F45: =IF(B45>0,(E45-B45)/B45,0) -> #N/A
A49: 📏 BODY MEASUREMENTS
A50: Date | B50: Weight (kg) | C50: Chest (cm) | D50: Shoulders (cm) | E50: L Arm (cm) | F50: R Arm (cm) | G50: Waist (cm) | H50: Notes
A51: Start | B51: 78 | H51: Saturday
...

Sheet PR Log
A1: 🏆 PERSONAL RECORDS LOG
A3: Exercise | B3: Date | C3: Weight (kg) | D3: Reps | E3: Est. 1RM | F3: Previous 1RM | G3: Notes
A4: Barbell Bench Press | E4: =IF(AND(C4<>"",D4<>""),ROUND(C4*(1+D4/30),1),"")
A5: 45° Incline DB Press | E5: =IF(AND(C5<>"",D5<>""),ROUND(C5*(1+D5/30),1),"")
A6: Seated DB Shoulder Press | E6: =IF(AND(C6<>"",D6<>""),ROUND(C6*(1+D6/30),1),"")
A7: Neutral-Grip Lat Pulldown | E7: =IF(AND(C7<>"",D7<>""),ROUND(C7*(1+D7/30),1),"")
A8: Chest-Supported Row | E8: =IF(AND(C8<>"",D8<>""),ROUND(C8*(1+D8/30),1),"")
A9: Single-Arm DB Row | E9: =IF(AND(C9<>"",D9<>""),ROUND(C9*(1+D9/30),1),"")
A10: EZ-Bar Curl | E10: =IF(AND(C10<>"",D10<>""),ROUND(C10*(1+D10/30),1),"")
A11: Overhead Triceps Extension | E11: =IF(AND(C11<>"",D11<>""),ROUND(C11*(1+D11/30),1),"")
E12: =IF(AND(C12<>"",D12<>""),ROUND(C12*(1+D12/30),1),"")
E13: =IF(AND(C13<>"",D13<>""),ROUND(C13*(1+D13/30),1),"")
E14: =IF(AND(C14<>"",D14<>""),ROUND(C14*(1+D14/30),1),"")
E15: =IF(AND(C15<>"",D15<>""),ROUND(C15*(1+D15/30),1),"")
E16: =IF(AND(C16<>"",D16<>""),ROUND(C16*(1+D16/30),1),"")
E17: =IF(AND(C17<>"",D17<>""),ROUND(C17*(1+D17/30),1),"")
E18: =IF(AND(C18<>"",D18<>""),ROUND(C18*(1+D18/30),1),"")
E19: =IF(AND(C19<>"",D19<>""),ROUND(C19*(1+D19/30),1),"")
E20: =IF(AND(C20<>"",D20<>""),ROUND(C20*(1+D20/30),1),"")
E21: =IF(AND(C21<>"",D21<>""),ROUND(C21*(1+D21/30),1),"")
E22: =IF(AND(C22<>"",D22<>""),ROUND(C22*(1+D22/30),1),"")
E23: =IF(AND(C23<>"",D23<>""),ROUND(C23*(1+D23/30),1),"")
... E31: =IF(AND(C31<>"",D31<>""),ROUND(C31*(1+D31/30),1),"")

Sheet Warm-up Calculator
A1: 🔥 WARM-UP WEIGHT CALCULATOR
A3: Enter your target working weight and get warm-up weights automatically.
A5: Exercise | B5: Target Weight | C5: Warm-up 1 (50%) | D5: Warm-up 2 (70%) | E5: Warm-up 3 (85%)
A6: Barbell Bench Press | B6: 15 | C6: =IF(B6<>"",ROUND(B6*0.5,1),"") -> 7.5 | D6: =IF(B6<>"",ROUND(B6*0.7,1),"") -> 10.5 | E6: =IF(B6<>"",ROUND(B6*0.85,1),"") -> 12.8
A7: 45° Incline DB Press | B7: 15 | C7: =IF(B7<>"",ROUND(B7*0.5,1),"") -> 7.5 | D7: =IF(B7<>"",ROUND(B7*0.7,1),"") -> 10.5 | E7: =IF(B7<>"",ROUND(B7*0.85,1),"") -> 12.8
A8: Seated DB Shoulder Press | B8: 5 | C8: =IF(B8<>"",ROUND(B8*0.5,1),"") -> 2.5 | D8: =IF(B8<>"",ROUND(B8*0.7,1),"") -> 3.5 | E8: =IF(B8<>"",ROUND(B8*0.85,1),"") -> 4.3
A9: Neutral-Grip Lat Pulldown | B9: 30 | C9: =IF(B9<>"",ROUND(B9*0.5,1),"") -> 15 | D9: =IF(B9<>"",ROUND(B9*0.7,1),"") -> 21 | E9: =IF(B9<>"",ROUND(B9*0.85,1),"") -> 25.5
A10: Chest-Supported Row | B10: 75 | C10: =IF(B10<>"",ROUND(B10*0.5,1),"") -> 37.5 | D10: =IF(B10<>"",ROUND(B10*0.7,1),"") -> 52.5 | E10: =IF(B10<>"",ROUND(B10*0.85,1),"") -> 63.8
A11: Single-Arm DB Row | B11: 10 | C11: =IF(B11<>"",ROUND(B11*0.5,1),"") -> 5 | D11: =IF(B11<>"",ROUND(B11*0.7,1),"") -> 7 | E11: =IF(B11<>"",ROUND(B11*0.85,1),"") -> 8.5
A12: EZ-Bar Curl | B12: 25 | C12: =IF(B12<>"",ROUND(B12*0.5,1),"") -> 12.5 | D12: =IF(B12<>"",ROUND(B12*0.7,1),"") -> 17.5 | E12: =IF(B12<>"",ROUND(B12*0.85,1),"") -> 21.3
A13: Overhead Triceps Extension | B13: 27 | C13: =IF(B13<>"",ROUND(B13*0.5,1),"") -> 13.5 | D13: =IF(B13<>"",ROUND(B13*0.7,1),"") -> 18.9 | E13: =IF(B13<>"",ROUND(B13*0.85,1),"") -> 23
C14: =IF(B14<>"",ROUND(B14*0.5,1),"") | D14: =IF(B14<>"",ROUND(B14*0.7,1),"") | E14: =IF(B14<>"",ROUND(B14*0.85,1),"")
C15: =IF(B15<>"",ROUND(B15*0.5,1),"") | D15: =IF(B15<>"",ROUND(B15*0.7,1),"") | E15: =IF(B15<>"",ROUND(B15*0.85,1),"")
C16: =IF(B16<>"",ROUND(B16*0.5,1),"") | D16: =IF(B16<>"",ROUND(B16*0.7,1),"") | E16: =IF(B16<>"",ROUND(B16*0.85,1),"")
C17: =IF(B17<>"",ROUND(B17*0.5,1),"") | D17: =IF(B17<>"",ROUND(B17*0.7,1),"") | E17: =IF(B17<>"",ROUND(B17*0.85,1),"")
C18: =IF(B18<>"",ROUND(B18*0.5,1),"") | D18: =IF(B18<>"",ROUND(B18*0.7,1),"") | E18: =IF(B18<>"",ROUND(B18*0.85,1),"")
C19: =IF(B19<>"",ROUND(B19*0.5,1),"") | D19: =IF(B19<>"",ROUND(B19*0.7,1),"") | E19: =IF(B19<>"",ROUND(B19*0.85,1),"")
C20: =IF(B20<>"",ROUND(B20*0.5,1),"") | D20: =IF(B20<>"",ROUND(B20*0.7,1),"") | E20: =IF(B20<>"",ROUND(B20*0.85,1),"")
C21: =IF(B21<>"",ROUND(B21*0.5,1),"") | D21: =IF(B21<>"",ROUND(B21*0.7,1),"") | E21: =IF(B21<>"",ROUND(B21*0.85,1),"")
C22: =IF(B22<>"",ROUND(B22*0.5,1),"") | D22: =IF(B22<>"",ROUND(B22*0.7,1),"") | E22: =IF(B22<>"",ROUND(B22*0.85,1),"")
C23: =IF(B23<>"",ROUND(B23*0.5,1),"") | D23: =IF(B23<>"",ROUND(B23*0.7,1),"") | E23: =IF(B23<>"",ROUND(B23*0.85,1),"")

Sheet Session A
A1: SESSION A
A3: 💪 Complete 1x per week | Alternate with the other session for 2x weekly frequency per muscle group | Rest 2-3 min (compounds), 60-90 sec (isolation)
A6: Exercise | B6: Type | C6: Muscles Worked
A7: Barbell Bench Press | B7: PUSH | C7: Chest, Front Delts, Triceps
A8: Neutral-Grip Lat Pulldown | B8: PULL | C8: Lats, Biceps, Rear Delts
A9: Seated Dumbbell Shoulder Press | B9: PUSH | C9: Shoulders (All), Triceps
A10: Chest-Supported Machine Row | B10: PULL | C10: Mid Back, Lats, Biceps
A11: Dumbbell Flye | B11: PUSH | C11: Chest (Stretch), Front Delts
A12: EZ-Bar or Dumbbell Curl | B12: PULL | C12: Biceps
A13: Dead Bug | B13: CORE | C13: Core (Anti-Extension)
A16: WEEK 1 - 2 SETS, RPE 7
A18: Flat Dumbbell Press / Machine Press instead | K18: 🎯 Chest, Front Delts, Triceps
A19: Set Type | B19: Target Reps | C19: Target RPE | D19: Weight (kg) | E19: Actual Reps | F19: Actual RPE | G19: Set Volume | H19: Est. 1RM | I19: Notes | J19: Session | K19: Muscle | L19: Sets Count
A20: Warm-up 1 | B20: 8-10 | D20: 2.5 | E20: 10
A21: Warm-up 2 | B21: 5-6 | D21: 5 | E21: 6
A22: Warm-up 3 | B22: 3-4 | D22: 7.5 | E22: 10
A23: Working 1 | B23: 8-10 | C23: 7 | D23: 10 | E23: 10 | F23: 8 | G23: =IF(AND(D23<>"",E23<>""),D23*E23,0) -> 100 | H23: =IF(AND(D23<>"",E23<>""),ROUND(D23*(1+E23/30),1),"") -> 13.3
A24: Working 2 | B24: 8-10 | C24: 7 | D24: 10 | E24: 10 | F24: 8 | G24: =IF(AND(D24<>"",E24<>""),D24*E24,0) -> 100 | H24: =IF(AND(D24<>"",E24<>""),ROUND(D24*(1+E24/30),1),"") -> 13.3
A25: Exercise Volume | G25: =G23+G24 -> 200 | H25: =MAX(H23,H24) -> 13.3 | J25: 1 | K25: Chest | L25: 2
A26: Substitutions: | B26: DB Bench Press, Machine Chest Press
A27: Form Notes: | B27: Pause 1 sec at bottom. Retract shoulder blades.
A29: Neutral-Grip Lat Pulldown | K29: 🎯 Lats, Biceps, Rear Delts
A30: Set Type | B30: Target Reps | C30: Target RPE | D30: Weight (kg) | E30: Actual Reps | F30: Actual RPE | G30: Set Volume | H30: Est. 1RM | I30: Notes | J30: Session | K30: Muscle | L30: Sets Count
A31: Warm-up 1 | B31: 10-12 | D31: 16 | E31: 10
A32: Warm-up 2 | B32: 6-8 | D32: 20 | E32: 8
A33: Working 1 | B33: 8-10 | C33: 7 | D33: 25 | E33: 10 | F33: 7 | G33: =IF(AND(D33<>"",E33<>""),D33*E33,0) -> 250 | H33: =IF(AND(D33<>"",E33<>""),ROUND(D33*(1+E33/30),1),"") -> 33.3
A34: Working 2 | B34: 8-10 | C34: 7 | D34: 30 | E34: 10 | F34: 8 | G34: =IF(AND(D34<>"",E34<>""),D34*E34,0) -> 300 | H34: =IF(AND(D34<>"",E34<>""),ROUND(D34*(1+E34/30),1),"") -> 40
A35: Exercise Volume | G35: =G33+G34 -> 550 | H35: =MAX(H33,H34) -> 40 | J35: 1 | K35: Back | L35: 2
A36: Substitutions: | B36: Wide-Grip Pulldown, Assisted Pull-ups
A37: Form Notes: | B37: Lean back slightly. Pull to chest.
A39: Seated Dumbbell Shoulder Press | K39: 🎯 Shoulders (All), Triceps
A40: Set Type | B40: Target Reps | C40: Target RPE | D40: Weight (kg) | E40: Actual Reps | F40: Actual RPE | G40: Set Volume | H40: Est. 1RM | I40: Notes | J40: Session | K40: Muscle | L40: Sets Count
A41: Warm-up 1 | B41: 8-10 | D41: 3 | E41: 10
A42: Warm-up 2 | B42: 45783 | D42: 5 | E42: 6
A43: Warm-up 3 | B43: 45720
A44: Working 1 | B44: 10-12 | C44: 7 | D44: 7.5 | E44: 10 | F44: 8 | G44: =IF(AND(D44<>"",E44<>""),D44*E44,0) -> 75 | H44: =IF(AND(D44<>"",E44<>""),ROUND(D44*(1+E44/30),1),"") -> 10
A45: Working 2 | B45: 10-12 | C45: 7 | D45: 7.5 | E45: 10 | G45: =IF(AND(D45<>"",E45<>""),D45*E45,0) -> 75 | H45: =IF(AND(D45<>"",E45<>""),ROUND(D45*(1+E45/30),1),"") -> 10
A46: Exercise Volume | G46: =G44+G45 -> 150 | H46: =MAX(H44,H45) -> 10 | J46: 1 | K46: Shoulders | L46: 2
A47: Substitutions: | B47: Standing DB Press, Arnold Press
A48: Form Notes: | B48: Elbows break 90°. Core tight.
...

Sheet Session B
A1: SESSION B
A3: 💪 Complete 1x per week | Alternate with the other session for 2x weekly frequency per muscle group | Rest 2-3 min (compounds), 60-90 sec (isolation)
A6: Exercise | B6: Type | C6: Muscles Worked
A7: 45° Incline Dumbbell Press | B7: PUSH | C7: Upper Chest, Front Delts, Triceps
A8: Single-Arm Dumbbell Row | B8: PULL | C8: Lats, Mid Back, Biceps
A9: Dumbbell Lateral Raise | B9: PUSH | C9: Side Delts
A10: Face Pull (Band or Cable) | B10: PULL | C10: Rear Delts, Upper Back
A11: Overhead Triceps Extension (DB) | B11: PUSH | C11: Triceps (Long Head)
A12: Incline Dumbbell Curl | B12: PULL | C12: Biceps (Long Head)
A13: Bird-Dog | B13: CORE | C13: Core (Anti-Rotation), Glutes
A16: WEEK 1 - 2 SETS, RPE 7
A18: 45° Incline Dumbbell Press | K18: 🎯 Upper Chest, Front Delts, Triceps
A19: Set Type | B19: Target Reps | C19: Target RPE | D19: Weight (kg) | E19: Actual Reps | F19: Actual RPE | G19: Set Volume | H19: Est. 1RM | I19: Notes | J19: Session | K19: Muscle | L19: Sets Count
A20: Warm-up 1 | B20: 8-10 | D20: 7.5 | E20: 10
A21: Warm-up 2 | B21: 45783 | D21: 10 | E21: 6
A22: Warm-up 3 | B22: 45720
A23: Working 1 | B23: 8-10 | C23: 7 | D23: 12.5 | E23: 10 | F23: 45878 | G23: =IF(AND(D23<>"",E23<>""),D23*E23,0) -> 125 | H23: =IF(AND(D23<>"",E23<>""),ROUND(D23*(1+E23/30),1),"") -> 16.7
A24: Working 2 | B24: 8-10 | C24: 7 | D24: 12.5 | E24: 9 | F24: 9 | G24: =IF(AND(D24<>"",E24<>""),D24*E24,0) -> 112.5 | H24: =IF(AND(D24<>"",E24<>""),ROUND(D24*(1+E24/30),1),"") -> 16.3
A25: Exercise Volume | G25: =G23+G24 -> 237.5 | H25: =MAX(H23,H24) -> 16.7 | J25: 1 | K25: Chest | L25: 2
A26: Substitutions: | B26: Incline Barbell Press, Incline Machine
A27: Form Notes: | B27: Elbows at 45°. Full stretch at bottom.
A29: Peck Deck Machine, Peck Fly Instead | K29: Pecks
A30: Set Type | B30: Target Reps | C30: Target RPE | D30: Weight (kg) | E30: Actual Reps | F30: Actual RPE | G30: Set Volume | H30: Est. 1RM | I30: Notes | J30: Session | L30: Sets Count
A31: Warm-up 1 | B31: 8-10 | D31: 3
A32: Working 1 | B32: 12 | C32: 8 | D32: 5 | E32: 10 | F32: 7 | G32: =IF(AND(D32<>"",E32<>""),D32*E32,0) -> 50 | H32: =IF(AND(D32<>"",E32<>""),ROUND(D32*(1+E32/30),1),"") -> 6.7
A33: Working 2 | B33: 12 | C33: 8 | D33: 5 | E33: 12 | F33: 8 | G33: =IF(AND(D33<>"",E33<>""),D33*E33,0) -> 60 | H33: =IF(AND(D33<>"",E33<>""),ROUND(D33*(1+E33/30),1),"") -> 7
A34: Exercise Volume | G34: =G32+G33 -> 110 | H34: =MAX(H30,H33) -> 7 | J34: 1 | K34: Chest | L34: 2
A35: Substitutions: | B35: Peck fly DB
A36: Form Notes:
A38: Cable Machine Row | K38: 🎯 Lats, Mid Back, Biceps
A39: Set Type | B39: Target Reps | C39: Target RPE | D39: Weight (kg) | E39: Actual Reps | F39: Actual RPE | G39: Set Volume | H39: Est. 1RM | I39: Notes | J39: Session | K39: Muscle | L39: Sets Count
A40: Warm-up 1 | B40: 8-10 | D40: 18 | E40: 10
A41: Warm-up 2 | B41: 45783 | D41: 25 | E41: 6
B42: 45692 | D42: 32 | E42: 4
A43: Working 1 | B43: 8-10 | C43: 7 | D43: 38 | E43: 10 | F43: 7 | G43: =IF(AND(D43<>"",E43<>""),D43*E43,0) -> 380 | H43: =IF(AND(D43<>"",E43<>""),ROUND(D43*(1+E43/30),1),"") -> 50.7
A44: Working 2 | B44: 8-10 | C44: 7 | D44: 38 | E44: 10 | F44: 7 | G44: =IF(AND(D44<>"",E44<>""),D44*E44,0) -> 380 | H44: =IF(AND(D44<>"",E44<>""),ROUND(D44*(1+E44/30),1),"") -> 50.7
A45: Exercise Volume | G45: =G43+G44 -> 760 | H45: =MAX(H43,H44) -> 50.7 | J45: 1 | K45: Back | L45: 2
A46: Substitutions: | B46: Single-Arm Dumbbell Row
A47: Form Notes: | B47: Pull to hip. Full stretch.
A49: Dumbbell Lateral Raise | K49: 🎯 Side Delts
...
